<?xml version="1.0" ?>
<!-- =================================================================================== -->
<!-- |    This document was autogenerated by xacro from ur5_robotiq85_gripper.urdf.xacro | -->
<!-- |    EDITING THIS FILE BY HAND IS NOT RECOMMENDED                                 | -->
<!-- =================================================================================== -->
<robot name="ur5">
  <gazebo>
    <plugin filename="libgazebo_ros_control.so" name="ros_control">
      <!--robotNamespace>/</robotNamespace-->
      <!--robotSimType>gazebo_ros_control/DefaultRobotHWSim</robotSimType-->
    </plugin>
    <!--
    <plugin name="gazebo_ros_power_monitor_controller" filename="libgazebo_ros_power_monitor.so">
      <alwaysOn>true</alwaysOn>
      <updateRate>1.0</updateRate>
      <timeout>5</timeout>
      <powerStateTopic>power_state</powerStateTopic>
      <powerStateRate>10.0</powerStateRate>
      <fullChargeCapacity>87.78</fullChargeCapacity>     
      <dischargeRate>-474</dischargeRate>
      <chargeRate>525</chargeRate>
      <dischargeVoltage>15.52</dischargeVoltage>
      <chargeVoltage>16.41</chargeVoltage>
    </plugin>
-->
  </gazebo>
  <!-- measured from model -->
  <!--property name="shoulder_height" value="0.089159" /-->
  <!--property name="shoulder_offset" value="0.13585" /-->
  <!-- shoulder_offset - elbow_offset + wrist_1_length = 0.10915 -->
  <!--property name="upper_arm_length" value="0.42500" /-->
  <!--property name="elbow_offset" value="0.1197" /-->
  <!-- CAD measured -->
  <!--property name="forearm_length" value="0.39225" /-->
  <!--property name="wrist_1_length" value="0.093" /-->
  <!-- CAD measured -->
  <!--property name="wrist_2_length" value="0.09465" /-->
  <!-- In CAD this distance is 0.930, but in the spec it is 0.09465 -->
  <!--property name="wrist_3_length" value="0.0823" /-->
  <!-- manually measured -->
  <link name="base_link">
    <visual>
      <origin xyz="0 0 0" rpy="1.5708 0 0" />
      <geometry>
        <mesh filename="meshes/ur5/visual/base.glb"/>
      </geometry>
    </visual>
    <collision>
      <geometry>
        <mesh filename="meshes/ur5/collision/base.stl"/>
      </geometry>
    </collision>
    <inertial>
      <mass value="4.0"/>
      <origin rpy="0 0 0" xyz="0.0 0.0 0.0"/>
      <inertia ixx="0.00443333156" ixy="0.0" ixz="0.0" iyy="0.00443333156" iyz="0.0" izz="0.0072"/>
    </inertial>
  </link>
  <joint name="shoulder_pan_joint" type="revolute">
    <parent link="base_link"/>
    <child link="shoulder_link"/>
    <origin rpy="0.0 0.0 0.0" xyz="0.0 0.0 0.089159"/>
    <axis xyz="0 0 1"/>
    <limit effort="150.0" lower="-3.142" upper="3.142" velocity="3.15"/>
    <dynamics damping="0.0" friction="0.0"/>
  </joint>
  <link name="shoulder_link">
    <visual>
      <origin xyz="0 0 0" rpy="1.5708 0 0" />
      <geometry>
        <mesh filename="meshes/ur5/visual/shoulder.glb"/>
      </geometry>
    </visual>
    <collision>
      <geometry>
        <mesh filename="meshes/ur5/collision/shoulder.stl"/>
      </geometry>
    </collision>
    <inertial>
      <mass value="3.7"/>
      <origin rpy="0 0 0" xyz="0.0 0.0 0.0"/>
      <inertia ixx="0.010267495893" ixy="0.0" ixz="0.0" iyy="0.010267495893" iyz="0.0" izz="0.00666"/>
    </inertial>
  </link>
  <joint name="shoulder_lift_joint" type="revolute">
    <parent link="shoulder_link"/>
    <child link="upper_arm_link"/>
    <origin rpy="0.0 1.5707963267948966 0.0" xyz="0.0 0.13585 0.0"/>
    <axis xyz="0 1 0"/>
    <limit effort="150.0" lower="-3.142" upper="0" velocity="3.15"/>
    <dynamics damping="0.0" friction="0.0"/>
  </joint>
  <link name="upper_arm_link">
    <visual>
      <origin xyz="0 0 0" rpy="1.5708 0 0" />
      <geometry>
        <mesh filename="meshes/ur5/visual/upperarm.glb"/>
      </geometry>
    </visual>
    <collision>
      <geometry>
        <mesh filename="meshes/ur5/collision/upperarm.stl"/>
      </geometry>
    </collision>
    <inertial>
      <mass value="8.393"/>
      <origin rpy="0 0 0" xyz="0.0 0.0 0.28"/>
      <inertia ixx="0.22689067591036005" ixy="0.0" ixz="0.0" iyy="0.22689067591036005" iyz="0.0" izz="0.0151074"/>
    </inertial>
  </link>
  <joint name="elbow_joint" type="revolute">
    <parent link="upper_arm_link"/>
    <child link="forearm_link"/>
    <origin rpy="0.0 0.0 0.0" xyz="0.0 -0.1197 0.425"/>
    <axis xyz="0 1 0"/>
    <limit effort="150.0" lower="-3.142" upper="3.142" velocity="3.15"/>
    <dynamics damping="0.0" friction="0.0"/>
  </joint>
  <link name="forearm_link">
    <visual>
      <origin xyz="0 0 0" rpy="1.5708 0 0" />
      <geometry>
        <mesh filename="meshes/ur5/visual/forearm.glb"/>
      </geometry>
    </visual>
    <collision>
      <geometry>
        <mesh filename="meshes/ur5/collision/forearm.stl"/>
      </geometry>
    </collision>
    <inertial>
      <mass value="2.275"/>
      <origin rpy="0 0 0" xyz="0.0 0.0 0.196125"/>
      <inertia ixx="0.03121679102890359" ixy="0.0" ixz="0.0" iyy="0.03121679102890359" iyz="0.0" izz="0.004095"/>
    </inertial>
  </link>
  <joint name="wrist_1_joint" type="revolute">
    <parent link="forearm_link"/>
    <child link="wrist_1_link"/>
    <origin rpy="0.0 1.5707963267948966 0.0" xyz="0.0 0.0 0.39225"/>
    <axis xyz="0 1 0"/>
    <limit effort="100.0" lower="-1.75" upper="1.75" velocity="3.2"/>
    <dynamics damping="0.0" friction="0.0"/>
  </joint>
  <link name="wrist_1_link">
    <visual>
      <origin xyz="0 0 0" rpy="1.5708 0 0" />
      <geometry>
        <mesh filename="meshes/ur5/visual/wrist1.glb"/>
      </geometry>
    </visual>
    <collision>
      <geometry>
        <mesh filename="meshes/ur5/collision/wrist1.stl"/>
      </geometry>
    </collision>
    <inertial>
      <mass value="1.219"/>
      <origin rpy="0 0 0" xyz="0.0 0.093 0.0"/>
      <inertia ixx="0.0025598989760400002" ixy="0.0" ixz="0.0" iyy="0.0025598989760400002" iyz="0.0" izz="0.0021942"/>
    </inertial>
  </link>
  <joint name="wrist_2_joint" type="revolute">
    <parent link="wrist_1_link"/>
    <child link="wrist_2_link"/>
    <origin rpy="0.0 0.0 0.0" xyz="0.0 0.093 0.0"/>
    <axis xyz="0 0 1"/>
    <limit effort="100.0" lower="-3.141592653589793" upper="3.141592653589793" velocity="3.2"/>
    <dynamics damping="0.0" friction="0.0"/>
  </joint>
  <link name="wrist_2_link">
    <visual>
      <origin xyz="0 0 0" rpy="1.5708 0 0" />
      <geometry>
        <mesh filename="meshes/ur5/visual/wrist2.glb"/>
      </geometry>
    </visual>
    <collision>
      <geometry>
        <mesh filename="meshes/ur5/collision/wrist2.stl"/>
      </geometry>
    </collision>
    <inertial>
      <mass value="1.219"/>
      <origin rpy="0 0 0" xyz="0.0 0.0 0.09465"/>
      <inertia ixx="0.0025598989760400002" ixy="0.0" ixz="0.0" iyy="0.0025598989760400002" iyz="0.0" izz="0.0021942"/>
    </inertial>
  </link>
  <joint name="wrist_3_joint" type="revolute">
    <parent link="wrist_2_link"/>
    <child link="wrist_3_link"/>
    <origin rpy="0.0 0.0 0.0" xyz="0.0 0.0 0.09465"/>
    <axis xyz="0 1 0"/>
    <limit effort="100.0" lower="-3.141592653589793" upper="3.141592653589793" velocity="3.2"/>
    <dynamics damping="0.0" friction="0.0"/>
  </joint>
  <link name="wrist_3_link">
    <visual>
      <origin xyz="0 0 0" rpy="1.5708 0 0" />
      <geometry>
        <mesh filename="meshes/ur5/visual/wrist3.glb"/>
      </geometry>
    </visual>
    <collision>
      <geometry>
        <mesh filename="meshes/ur5/collision/wrist3.stl"/>
      </geometry>
    </collision>
    <inertial>
      <mass value="0.1879"/>
      <origin rpy="1.5707963267948966 0 0" xyz="0.0 0.06505 0.0"/>
      <inertia ixx="8.469589112163e-05" ixy="0.0" ixz="0.0" iyy="8.469589112163e-05" iyz="0.0" izz="0.0001321171875"/>
    </inertial>
  </link>
  <joint name="ee_fixed_joint" type="fixed">
    <parent link="wrist_3_link"/>
    <child link="ee_link"/>
    <origin rpy="0.0 0.0 1.5707963267948966" xyz="0.0 0.0823 0.0"/>
  </joint>
  <link name="ee_link">
    <collision>
      <geometry>
        <box size="0.01 0.01 0.01"/>
      </geometry>
      <origin rpy="0 0 0" xyz="-0.01 0 0"/>
    </collision>
  </link>

  <link name="camera_base">
    <visual>
      <origin rpy="0 0 1.57079632679" xyz="0 -0.0 0"/>
      <geometry>
        <mesh filename="meshes/ur5/visual/camera_base_ur5.glb" />
      </geometry>
    </visual>
  </link>
  <joint name="hand_to_camera_mount" type="fixed">
    <parent link="wrist_3_link"/>
    <child link="camera_base"/>
    <origin rpy="3.14159265359 1.57079632679 1.57079632679" xyz="0.0 0.08 0"/>
  </joint>

  <link name="camera">
    <visual>
      <origin rpy="3.8 0 1.5707963267948966" xyz="0.0 0.0 -0.0"/>
      <geometry>
        <mesh filename="meshes/ur5/visual/camera.glb" />
      </geometry>
    </visual>
  </link>
  <joint name="camera_joint" type="fixed">
    <parent link="camera_base"/>
    <child link="camera"/>
    <origin rpy="1.57079632679 1.5707963267948966 -1.57079632679" xyz="-0.075 0.0 -0.025"/>
  </joint>

  <!-- ROS base_link to UR 'Base' Coordinates transform -->
  <link name="base"/>
  <joint name="base_link-base_fixed_joint" type="fixed">
    <!-- NOTE: this rotation is only needed as long as base_link itself is
                 not corrected wrt the real robot (ie: rotated over 180
                 degrees)
      -->
    <origin rpy="0 0 -3.141592653589793" xyz="0 0 0"/>
    <parent link="base_link"/>
    <child link="base"/>
  </joint>
  <!-- Frame coincident with all-zeros TCP on UR controller -->
  <link name="tool0"/>
  <joint name="wrist_3_link-tool0_fixed_joint" type="fixed">
    <origin rpy="-1.5707963267948966 0 0" xyz="0 0.0823 0"/>
    <parent link="wrist_3_link"/>
    <child link="tool0"/>
  </joint>
  <link name="world"/>
  <joint name="world_joint" type="fixed">
    <parent link="world"/>
    <child link="base_link"/>
    <origin rpy="0.0 0.0 0.0" xyz="0.0 0.0 0.0"/>
  </joint>
  


  <joint name="wsg_base_joint" type="fixed">
    <parent link="ee_link"/>
    <child link="wsg_50_base_link"/>
    <origin rpy="1.5707 0 1.5707" xyz="0 0 0"/>
  </joint>



<!-- ********************** Start WSG ******************* -->
  <!-- BASE LINK -->
  <link name="wsg_50_base_link">
    <inertial>
      <mass value="1.2" />
      <origin xyz="0 0 0" />
      <!--inertia
      ixx="1.0" ixy="0.0" ixz="0.0"
           iyy="100.0" iyz="0.0" 
           izz="1.0" /-->
      <inertia ixx="1.0" ixy="0.0" ixz="0.0" iyy="1.0" iyz="0.0" izz="1.0" />
    </inertial>

    <visual>
      <origin xyz="0.0 0 0" rpy="0 0 0" />
      <geometry>
        <mesh filename="./meshes/gripper/WSG50_110.stl" scale="1 1 1" />
      </geometry>
      <material name="black">
        <color rgba="0.4 0.4 0.4 1" />
      </material>
    </visual>

    <collision>
      <origin xyz="0.0 0 0" rpy="0 0 0" />
      <geometry>
        <!--box
        size="0.146 0.05 0.0735"/-->
        <mesh filename="./meshes/gripper/WSG50_110.stl" scale="1 1 1" />
      </geometry>
    </collision>
  </link>
  
  <joint name="base_joint_gripper_left" type="prismatic">
    <limit lower="-0.055" upper="-0.0027" effort="1.0" velocity="1.0" />
    <origin xyz="0 0 0" rpy="0 0 0" />      <!--origin
    xyz="-0.0067 0 0.049" rpy="0 0 0" /-->
    <parent link="wsg_50_base_link" />
    <child link="gripper_left" />
    <dynamics friction="100" damping="100" />
    <axis xyz="1 0 0" />
    <limit effort="100" velocity="100" />
  </joint>

  <link name="gripper_left">
    <inertial>
      <mass value="0.1" />
      <origin xyz="0 0 0" />
      <inertia ixx="1.0" ixy="0.0" ixz="0.0"
        iyy="1.0" iyz="0.0"
        izz="1.0" />
    </inertial>

    <visual>
      <origin xyz="0.0 0 0" rpy="0 0 0" />
      <geometry>
        <mesh filename="./meshes/gripper/GUIDE_WSG50_110.stl"/>
      </geometry>
      <material name="black1">
        <color rgba="0.4 0.4 0.4 1" />
      </material>
    </visual>

    <collision>
      <origin xyz="0 0 0" rpy="0 0 0" />
      <geometry>
        <!--box
        size="0.0175 0.03 0.024"/-->
        <mesh filename="./meshes/gripper/GUIDE_WSG50_110.stl"  />
      </geometry>
    </collision>
  </link>

  <!-- LEFT FINGER -->
  <joint name="guide_joint_finger_left" type="fixed">
    <origin xyz="0 0 0.023" rpy="0 0 0" />
    <parent link="gripper_left" />
    <child link="finger_left" />
    <dynamics friction="100" damping="100" />
    <axis xyz="1 0 0" />
    <limit effort="100" velocity="100" />
  </joint>

  <link name="finger_left">
    <inertial>
      <mass value="0.1" />
      <origin xyz="0 0 0" />
      <inertia ixx="1.0" ixy="0.0" ixz="0.0"
        iyy="1.0" iyz="0.0"
        izz="1.0" />
    </inertial>

    <visual>
      <origin xyz="0.0 0 0" rpy="0 0 0" />
      <geometry>
        <mesh filename="./meshes/gripper/WSG-FMF.stl"  />
      </geometry>
      <material name="black2">
        <color rgba="0.4 0.4 0.4 1" />
      </material>
    </visual>

    <collision>
      <origin xyz="0 0 0" rpy="0 0 0" />
      <geometry>
        <mesh filename="./meshes/gripper/WSG-FMF.stl"  />
      </geometry>
    </collision>
  </link>

  <!-- GRIPPER RIGHT -->
  <joint name="base_joint_gripper_right" type="prismatic">
    <limit lower="0.0027" upper="0.055" effort="1.0" velocity="1.0" />
    <origin xyz="0 0 0" rpy="0 0 3.14159" />
    <parent link="wsg_50_base_link" />
    <child link="gripper_right" />
    <axis xyz="-1 0 0" />
    <dynamics friction="100" damping="100" />
    <limit effort="100" velocity="100" />
  </joint>

  <link name="gripper_right">
    <inertial>
      <mass value="0.1" />
      <origin xyz="0 0 0" />
      <inertia ixx="1.0" ixy="0.0" ixz="0.0"
        iyy="1.0" iyz="0.0"
        izz="1.0" />
    </inertial>

    <visual>
      <origin xyz="0.0 0 0" rpy="0 0 0" />
      <geometry>
        <mesh filename="./meshes/gripper/GUIDE_WSG50_110.stl"  />
      </geometry>
      <material name="black">
        <color rgba="0.6 0.6 0.6 1" />
      </material>
    </visual>

    <collision>
      <origin xyz="0 0 0" rpy="0 0 0" />
      <geometry>
        <mesh filename="./meshes/gripper/GUIDE_WSG50_110.stl"  />
      </geometry>
    </collision>
  </link>

  <!-- RIGHT FINGER -->
  <joint name="guide_joint_finger_right" type="fixed">
    <origin xyz="0 0 0.023" rpy="0 0 0" />
    <parent link="gripper_right" />
    <child link="finger_right" />
    <dynamics friction="100" damping="100" />
    <axis xyz="1 0 0" />
    <limit effort="100" velocity="100" />
  </joint>

  <link name="finger_right">
    <inertial>
      <mass value="0.1" />
      <origin xyz="0 0 0" />
      <inertia ixx="1.0" ixy="0.0" ixz="0.0"
        iyy="1.0" iyz="0.0"
        izz="1.0" />
    </inertial>

    <visual>
      <origin xyz="0.0 0 0" rpy="0 0 0" />
      <geometry>
        <mesh filename="./meshes/gripper/WSG-FMF.stl"  />
      </geometry>
      <material name="black">
        <color rgba="0.4 0.4 0.4 1" />
      </material>
    </visual>

    <collision>
      <origin xyz="0 0 0" rpy="0 0 0" />
      <geometry>
        <mesh filename="./meshes/gripper/WSG-FMF.stl"  />
      </geometry>
    </collision>
  </link>
  <!-- ******************* end WSG ********************** -->
</robot>
